2024-09-10 17:22:32.626 | ERROR    | withdrawal.okx_actions:collect_funds_from_subaccounts:45 - cannot withdraw from acc 146gdhc, name 'aiohttp_params' is not defined
2024-09-10 17:23:04.580 | ERROR    | withdrawal.okx_actions:collect_funds_from_subaccounts:45 - cannot withdraw from acc 146gdhc, name 'aiohttp_params' is not defined
2024-09-10 18:38:15.425 | ERROR    | __main__:main:20 - cannot withdraw to 0x71B4A1BA05A360bBf96A70B93D6d93416B064cC3, invalid literal for int() with base 10: 'Failed to withdraw from OKX | can not get fee for withdraw'
2024-09-10 18:40:31.933 | ERROR    | withdrawal.okx_actions:withdraw:107 - withdraw: 51000, Parameter fee error
Traceback (most recent call last):

  File "/Users/daniilgaripov/Documents/scripts/stylus_arbitrum/withdrawal/main.py", line 25, in <module>
    asyncio.run(main(wallet='0x71B4A1BA05A360bBf96A70B93D6d93416B064cC3', amount=0.001))
    │       │   └ <function main at 0x104b8cc20>
    │       └ <function run at 0x118637880>
    └ <module 'asyncio' from '/Library/Frameworks/Python.framework/Versions/3.11/lib/python3.11/asyncio/__init__.py'>

  File "/Library/Frameworks/Python.framework/Versions/3.11/lib/python3.11/asyncio/runners.py", line 190, in run
    return runner.run(main)
           │      │   └ <coroutine object main at 0x1186f7640>
           │      └ <function Runner.run at 0x118637c40>
           └ <asyncio.runners.Runner object at 0x1064ed290>
  File "/Library/Frameworks/Python.framework/Versions/3.11/lib/python3.11/asyncio/runners.py", line 118, in run
    return self._loop.run_until_complete(task)
           │    │     │                  └ <Task pending name='Task-1' coro=<main() running at /Users/daniilgaripov/Documents/scripts/stylus_arbitrum/withdrawal/main.py...
           │    │     └ <function BaseEventLoop.run_until_complete at 0x118635800>
           │    └ <_UnixSelectorEventLoop running=True closed=False debug=False>
           └ <asyncio.runners.Runner object at 0x1064ed290>
  File "/Library/Frameworks/Python.framework/Versions/3.11/lib/python3.11/asyncio/base_events.py", line 640, in run_until_complete
    self.run_forever()
    │    └ <function BaseEventLoop.run_forever at 0x118635760>
    └ <_UnixSelectorEventLoop running=True closed=False debug=False>
  File "/Library/Frameworks/Python.framework/Versions/3.11/lib/python3.11/asyncio/base_events.py", line 607, in run_forever
    self._run_once()
    │    └ <function BaseEventLoop._run_once at 0x118637560>
    └ <_UnixSelectorEventLoop running=True closed=False debug=False>
  File "/Library/Frameworks/Python.framework/Versions/3.11/lib/python3.11/asyncio/base_events.py", line 1922, in _run_once
    handle._run()
    │      └ <function Handle._run at 0x118487ce0>
    └ <Handle <TaskStepMethWrapper object at 0x11bf90d30>()>
  File "/Library/Frameworks/Python.framework/Versions/3.11/lib/python3.11/asyncio/events.py", line 80, in _run
    self._context.run(self._callback, *self._args)
    │    │            │    │           │    └ <member '_args' of 'Handle' objects>
    │    │            │    │           └ <Handle <TaskStepMethWrapper object at 0x11bf90d30>()>
    │    │            │    └ <member '_callback' of 'Handle' objects>
    │    │            └ <Handle <TaskStepMethWrapper object at 0x11bf90d30>()>
    │    └ <member '_context' of 'Handle' objects>
    └ <Handle <TaskStepMethWrapper object at 0x11bf90d30>()>

  File "/Users/daniilgaripov/Documents/scripts/stylus_arbitrum/withdrawal/main.py", line 16, in main
    id = await okx_actions.withdraw(to_address=wallet, amount=amount, token_symbol='ETH', chain=chain)
               │           │                   │              │                                 └ 'Arbitrum One'
               │           │                   │              └ 0.001
               │           │                   └ '0x71B4A1BA05A360bBf96A70B93D6d93416B064cC3'
               │           └ <function OKXActions.withdraw at 0x11bf87b00>
               └ <withdrawal.okx_actions.OKXActions object at 0x11bf9f3d0>

> File "/Users/daniilgaripov/Documents/scripts/stylus_arbitrum/withdrawal/okx_actions.py", line 95, in withdraw
    withdrawal_token = await self.okx_client.asset.withdrawal(
                             │    │          │     └ <function Asset.withdrawal at 0x11bf87240>
                             │    │          └ <libs.py_okx_async.asset.Asset.Asset object at 0x11ba6da90>
                             │    └ <libs.py_okx_async.OKXClient.OKXClient object at 0x11bf9f410>
                             └ <withdrawal.okx_actions.OKXActions object at 0x11bf9f3d0>

  File "/Users/daniilgaripov/Documents/scripts/stylus_arbitrum/libs/py_okx_async/asset/Asset.py", line 227, in withdrawal
    response = await self.make_request(
                     │    └ <function Base.make_request at 0x11bf86160>
                     └ <libs.py_okx_async.asset.Asset.Asset object at 0x11ba6da90>

  File "/Users/daniilgaripov/Documents/scripts/stylus_arbitrum/libs/py_okx_async/Base.py", line 120, in make_request
    response = await async_post(
                     └ <function async_post at 0x11bf85bc0>

  File "/Users/daniilgaripov/Documents/scripts/stylus_arbitrum/libs/py_okx_async/utils.py", line 56, in async_post
    raise exceptions.APIException(response=response, status_code=status_code)
          │          │                     │                     └ 400
          │          │                     └ {'code': '51000', 'data': [], 'msg': 'Parameter fee error'}
          │          └ <class 'libs.py_okx_async.exceptions.APIException'>
          └ <module 'libs.py_okx_async.exceptions' from '/Users/daniilgaripov/Documents/scripts/stylus_arbitrum/libs/py_okx_async/excepti...

libs.py_okx_async.exceptions.APIException: 51000, Parameter fee error
2024-09-10 18:40:31.939 | ERROR    | __main__:main:20 - cannot withdraw to 0x71B4A1BA05A360bBf96A70B93D6d93416B064cC3, invalid literal for int() with base 10: 'Failed to withdraw from OKX: 51000, Parameter fee error'
2024-09-10 18:41:33.084 | ERROR    | withdrawal.okx_actions:withdraw:108 - withdraw: 51000, Parameter fee error
Traceback (most recent call last):

  File "/Users/daniilgaripov/Documents/scripts/stylus_arbitrum/withdrawal/main.py", line 25, in <module>
    asyncio.run(main(wallet='0x71B4A1BA05A360bBf96A70B93D6d93416B064cC3', amount=0.001))
    │       │   └ <function main at 0x1044acc20>
    │       └ <function run at 0x1075ff880>
    └ <module 'asyncio' from '/Library/Frameworks/Python.framework/Versions/3.11/lib/python3.11/asyncio/__init__.py'>

  File "/Library/Frameworks/Python.framework/Versions/3.11/lib/python3.11/asyncio/runners.py", line 190, in run
    return runner.run(main)
           │      │   └ <coroutine object main at 0x112c50ee0>
           │      └ <function Runner.run at 0x1075ffc40>
           └ <asyncio.runners.Runner object at 0x107611bd0>
  File "/Library/Frameworks/Python.framework/Versions/3.11/lib/python3.11/asyncio/runners.py", line 118, in run
    return self._loop.run_until_complete(task)
           │    │     │                  └ <Task pending name='Task-1' coro=<main() running at /Users/daniilgaripov/Documents/scripts/stylus_arbitrum/withdrawal/main.py...
           │    │     └ <function BaseEventLoop.run_until_complete at 0x1075fd800>
           │    └ <_UnixSelectorEventLoop running=True closed=False debug=False>
           └ <asyncio.runners.Runner object at 0x107611bd0>
  File "/Library/Frameworks/Python.framework/Versions/3.11/lib/python3.11/asyncio/base_events.py", line 640, in run_until_complete
    self.run_forever()
    │    └ <function BaseEventLoop.run_forever at 0x1075fd760>
    └ <_UnixSelectorEventLoop running=True closed=False debug=False>
  File "/Library/Frameworks/Python.framework/Versions/3.11/lib/python3.11/asyncio/base_events.py", line 607, in run_forever
    self._run_once()
    │    └ <function BaseEventLoop._run_once at 0x1075ff560>
    └ <_UnixSelectorEventLoop running=True closed=False debug=False>
  File "/Library/Frameworks/Python.framework/Versions/3.11/lib/python3.11/asyncio/base_events.py", line 1922, in _run_once
    handle._run()
    │      └ <function Handle._run at 0x107587ce0>
    └ <Handle <TaskStepMethWrapper object at 0x112f10700>()>
  File "/Library/Frameworks/Python.framework/Versions/3.11/lib/python3.11/asyncio/events.py", line 80, in _run
    self._context.run(self._callback, *self._args)
    │    │            │    │           │    └ <member '_args' of 'Handle' objects>
    │    │            │    │           └ <Handle <TaskStepMethWrapper object at 0x112f10700>()>
    │    │            │    └ <member '_callback' of 'Handle' objects>
    │    │            └ <Handle <TaskStepMethWrapper object at 0x112f10700>()>
    │    └ <member '_context' of 'Handle' objects>
    └ <Handle <TaskStepMethWrapper object at 0x112f10700>()>

  File "/Users/daniilgaripov/Documents/scripts/stylus_arbitrum/withdrawal/main.py", line 16, in main
    id = await okx_actions.withdraw(to_address=wallet, amount=amount, token_symbol='ETH', chain=chain)
               │           │                   │              │                                 └ 'Arbitrum One'
               │           │                   │              └ 0.001
               │           │                   └ '0x71B4A1BA05A360bBf96A70B93D6d93416B064cC3'
               │           └ <function OKXActions.withdraw at 0x112f0bb00>
               └ <withdrawal.okx_actions.OKXActions object at 0x112f232d0>

> File "/Users/daniilgaripov/Documents/scripts/stylus_arbitrum/withdrawal/okx_actions.py", line 96, in withdraw
    withdrawal_token = await self.okx_client.asset.withdrawal(
                             │    │          │     └ <function Asset.withdrawal at 0x112f0b240>
                             │    │          └ <libs.py_okx_async.asset.Asset.Asset object at 0x110f343d0>
                             │    └ <libs.py_okx_async.OKXClient.OKXClient object at 0x112f23310>
                             └ <withdrawal.okx_actions.OKXActions object at 0x112f232d0>

  File "/Users/daniilgaripov/Documents/scripts/stylus_arbitrum/libs/py_okx_async/asset/Asset.py", line 227, in withdrawal
    response = await self.make_request(
                     │    └ <function Base.make_request at 0x112f0a160>
                     └ <libs.py_okx_async.asset.Asset.Asset object at 0x110f343d0>

  File "/Users/daniilgaripov/Documents/scripts/stylus_arbitrum/libs/py_okx_async/Base.py", line 120, in make_request
    response = await async_post(
                     └ <function async_post at 0x112f09bc0>

  File "/Users/daniilgaripov/Documents/scripts/stylus_arbitrum/libs/py_okx_async/utils.py", line 56, in async_post
    raise exceptions.APIException(response=response, status_code=status_code)
          │          │                     │                     └ 400
          │          │                     └ {'code': '51000', 'data': [], 'msg': 'Parameter fee error'}
          │          └ <class 'libs.py_okx_async.exceptions.APIException'>
          └ <module 'libs.py_okx_async.exceptions' from '/Users/daniilgaripov/Documents/scripts/stylus_arbitrum/libs/py_okx_async/excepti...

libs.py_okx_async.exceptions.APIException: 51000, Parameter fee error
2024-09-10 18:41:33.096 | ERROR    | __main__:main:20 - cannot withdraw to 0x71B4A1BA05A360bBf96A70B93D6d93416B064cC3, invalid literal for int() with base 10: 'Failed to withdraw from OKX: 51000, Parameter fee error'
2024-09-10 18:53:47.272 | ERROR    | tasks.mint:mint:32 - 0xe31270f155D10372FC9dC749cb2EfC3b4dC1cf59 did not mint nft :( !
2024-09-10 19:04:14.106 | ERROR    | tasks.mint:mint:36 - {'code': -32000, 'message': 'failed with 715160 gas: max fee per gas less than block base fee: address 0xFFEFa6965aCC0B56F3Ba163F4f4E230C19aFC70E, maxFeePerGas: 15268000, baseFee: 15300000'}
2024-09-10 19:05:38.801 | ERROR    | tasks.mint:mint:35 - {'code': -32000, 'message': 'failed with 726774 gas: max fee per gas less than block base fee: address 0xFFEFa6965aCC0B56F3Ba163F4f4E230C19aFC70E, maxFeePerGas: 15024001, baseFee: 15146000'}
2024-09-10 19:06:44.060 | ERROR    | tasks.mint:mint:35 - 0x517255FDc978E3ef67989af76b070098d8881D0b did not mint nft :( !
2024-09-10 19:10:00.414 | ERROR    | tasks.mint:mint:33 - 0xFFEFa6965aCC0B56F3Ba163F4f4E230C19aFC70E did not mint nft :( !
2024-09-10 19:13:55.538 | ERROR    | tasks.mint:mint:36 - 0x6d2f8e50
